Workbook

Sheet Легенда
A1: Дорожная карта брокерского бизнеса — модель метрик (этап 1)
A3: Документ | B3: Модель метрик брокерского бизнеса — этап 1 дорожной карты проектов
A4: Версия | B4: v0.2 — в работе, метрики на согласовании
A5: Назначение | B5: Единая система метрик, связывающая управляемые драйверы с маржинальным доходом (МД). На этапе 2 каждая гипотеза ссылается на код драйвера, а её эффект переводится в деньги через лист «Чувствительность».
A6: Статус данных | B6: Значения вводных иллюстративные: условный брокер среднего размера, ориентиры — публичные брокеры (см. колонку «Источник / ориентир» на листе «Вводные» и отчёт с бенчмарками в репозитории). Перед выводами замените жёлтые ячейки фактом.
A7: Надёжность ориентиров | B7: Цифры бенчмарков получены из поисковых выдержек первоисточников: прямой доступ к отчётам компаний был закрыт. Перед внешним использованием сверить с документами.
A8: Единицы | B8: у.е. — условные денежные единицы; все суммы — за период (год).
A10: Этапы
A11: 1. Метрики | B11: Этот файл: дерево, паспорта, модель, чувствительность — в работе, метрики на согласовании
A12: 2. Гипотезы | B12: Шаблон карты гипотез, привязка к драйверам — следующий шаг
A13: 3. Трудозатраты | B13: Оценка гипотез — после этапа 2
A14: 4. Дорожная карта | B14: Приоритизация и раскладка по времени — после этапа 3
A16: Листы
A17: Сводка | B17: P&L по сегментам, ключевые KPI, топ-10 драйверов по ценности улучшения
A18: Дерево | B18: Иерархия метрик от МД до драйверов с текущими значениями
A19: Вводные | B19: Все допущения модели по сегментам — редактировать здесь
A20: Чувствительность | B20: Ценность улучшения каждого драйвера на 1% и на практический шаг (1 п.п., 1 б.п.) — в горизонтах «год 1» и «долгосрочно»
A21: Модель | B21: Расчёт по сегментам; справа сгруппированы технические сценарии для чувствительности
A22: Паспорта | B22: Определения, формулы, источники данных, владельцы; опережающие индикаторы, ограничители, внешние факторы
A24: Цвета
A25: Вводная | B25: Синий шрифт на жёлтом фоне — допущения, которые нужно заменить фактом
A26: Формула | B26: Чёрный шрифт — расчёт
A27: Ссылка | B27: Зелёный шрифт — значение с другого листа
A29: Принятые решения
A30: Рынок | B30: Универсальная модель без привязки к юрисдикции; бенчмарки — публичные брокеры
A31: Сегменты | B31: Масс-розница, состоятельные, институционалы и корпоративные; B2B вне периметра
A32: Верх дерева | B32: Маржинальный доход; регуляторные задачи — отдельный обязательный трек без денежной оценки
A33: Формат | B33: Excel-модель + описание в markdown в репозитории
A34: Горизонт оценки | B34: Оба горизонта; гипотезы ранжируются по долгосрочному эффекту, бюджет проверяется по году 1
A35: Клиент | B35: Фондированный — активы от ≈$100 в эквиваленте; активный — любая операция за месяц
A36: Продукты | B36: «Выделение сервисов в продукты» — внутренние сервисы со своим P&L; учитывается только эффект брокера, без эффектов для группы
A37: Ставки | B37: План строится на сценарии снижения ставок (RATE_SHIFT, по умолчанию −1 п.п.)
A38: Данные | B38: Работаем на ориентирах публичных брокеров; факт подставим позже
A39: Апгрейд МР → СК | B39: Отдельным драйвером не моделируется, считается внутри гипотез
A40: Срок карты | B40: 3 года по полугодиям
A42: Как пользоваться
A43: Шаг 1 | B43: Замените значения на листе «Вводные» фактическими данными по сегментам
A44: Шаг 2 | B44: Сверьте «Сводку» с управленческой отчётностью: ЧВ и МД по сегментам должны совпасть (±5%)
A45: Шаг 3 | B45: На листе «Чувствительность» — сколько МД даёт улучшение каждого драйвера
A46: Шаг 4 | B46: HORIZON на листе «Вводные» переключает «Сводку» и «Дерево»: 1 — год 1 (P&L плана), 2 — run-rate на конец года, 3 — долгосрочно (база = NEW ÷ CHURN). «Чувствительность» всегда показывает горизонты 1 и 3 рядом
...

Sheet Сводка
A1: Сводка: экономика брокерского бизнеса по сегментам
A2: Значения иллюстративные до замены вводных фактическими данными. P&L и KPI — в режиме HORIZON (лист «Вводные»).
D3: Сдвиг ставок: | E3: =Вводные!$D$7 -> -0.01 | F3: Режим HORIZON: | G3: =Вводные!$D$6 -> 1
A4: Код | B4: P&L, у.е. за период | C4: Масс-розница | D4: Состоятельные | E4: Институционалы и корп. | F4: Итого | G4: Доля в ЧВ
A5: R1 | B5: Торговые комиссии (нетто) | C5: =INDEX(Модель!$E$8:$E$101,MATCH($A5,Модель!$A$8:$A$101,0)) -> 12268368 | D5: =INDEX(Модель!$F$8:$F$101,MATCH($A5,Модель!$A$8:$A$101,0)) -> 4188492 | E5: =INDEX(Модель!$G$8:$G$101,MATCH($A5,Модель!$A$8:$A$101,0)) -> 6020352 | F5: =INDEX(Модель!$H$8:$H$101,MATCH($A5,Модель!$A$8:$A$101,0)) -> 22477212 | G5: =IF($F$12<>0,F5/$F$12,0) -> 0.20602506
A6: R2 | B6: Маржинальное кредитование (нетто) | C6: =INDEX(Модель!$E$8:$E$101,MATCH($A6,Модель!$A$8:$A$101,0)) -> 10142500 | D6: =INDEX(Модель!$F$8:$F$101,MATCH($A6,Модель!$A$8:$A$101,0)) -> 6799500 | E6: =INDEX(Модель!$G$8:$G$101,MATCH($A6,Модель!$A$8:$A$101,0)) -> 6030000 | F6: =INDEX(Модель!$H$8:$H$101,MATCH($A6,Модель!$A$8:$A$101,0)) -> 22972000 | G6: =IF($F$12<>0,F6/$F$12,0) -> 0.21056026
A7: R3 | B7: Доход на свободные остатки (нетто) | C7: =INDEX(Модель!$E$8:$E$101,MATCH($A7,Модель!$A$8:$A$101,0)) -> 12171000 | D7: =INDEX(Модель!$F$8:$F$101,MATCH($A7,Модель!$A$8:$A$101,0)) -> 4835200 | E7: =INDEX(Модель!$G$8:$G$101,MATCH($A7,Модель!$A$8:$A$101,0)) -> 5025000 | F7: =INDEX(Модель!$H$8:$H$101,MATCH($A7,Модель!$A$8:$A$101,0)) -> 22031200 | G7: =IF($F$12<>0,F7/$F$12,0) -> 0.20193693
A8: R4 | B8: Конвертация валют | C8: =INDEX(Модель!$E$8:$E$101,MATCH($A8,Модель!$A$8:$A$101,0)) -> 3803437.5 | D8: =INDEX(Модель!$F$8:$F$101,MATCH($A8,Модель!$A$8:$A$101,0)) -> 2266500 | E8: =INDEX(Модель!$G$8:$G$101,MATCH($A8,Модель!$A$8:$A$101,0)) -> 804000 | F8: =INDEX(Модель!$H$8:$H$101,MATCH($A8,Модель!$A$8:$A$101,0)) -> 6873937.5 | G8: =IF($F$12<>0,F8/$F$12,0) -> 0.063006184
A9: R5 | B9: Размещения и продукты | C9: =INDEX(Модель!$E$8:$E$101,MATCH($A9,Модель!$A$8:$A$101,0)) -> 1217100 | D9: =INDEX(Модель!$F$8:$F$101,MATCH($A9,Модель!$A$8:$A$101,0)) -> 5076960 | E9: =INDEX(Модель!$G$8:$G$101,MATCH($A9,Модель!$A$8:$A$101,0)) -> 10050000 | F9: =INDEX(Модель!$H$8:$H$101,MATCH($A9,Модель!$A$8:$A$101,0)) -> 16344060 | G9: =IF($F$12<>0,F9/$F$12,0) -> 0.14980888
A10: R6 | B10: ДУ и консультирование | C10: =INDEX(Модель!$E$8:$E$101,MATCH($A10,Модель!$A$8:$A$101,0)) -> 811400 | D10: =INDEX(Модель!$F$8:$F$101,MATCH($A10,Модель!$A$8:$A$101,0)) -> 6044000 | E10: =INDEX(Модель!$G$8:$G$101,MATCH($A10,Модель!$A$8:$A$101,0)) -> 1507500 | F10: =INDEX(Модель!$H$8:$H$101,MATCH($A10,Модель!$A$8:$A$101,0)) -> 8362900 | G10: =IF($F$12<>0,F10/$F$12,0) -> 0.076653944
A11: R7 | B11: Подписки и сервисные комиссии | C11: =INDEX(Модель!$E$8:$E$101,MATCH($A11,Модель!$A$8:$A$101,0)) -> 3245600 | D11: =INDEX(Модель!$F$8:$F$101,MATCH($A11,Модель!$A$8:$A$101,0)) -> 3777500 | E11: =INDEX(Модель!$G$8:$G$101,MATCH($A11,Модель!$A$8:$A$101,0)) -> 3015000 | F11: =INDEX(Модель!$H$8:$H$101,MATCH($A11,Модель!$A$8:$A$101,0)) -> 10038100 | G11: =IF($F$12<>0,F11/$F$12,0) -> 0.092008747
A12: NR | B12: ЧВ — чистая выручка | C12: =INDEX(Модель!$E$8:$E$101,MATCH($A12,Модель!$A$8:$A$101,0)) -> 43659406 | D12: =INDEX(Модель!$F$8:$F$101,MATCH($A12,Модель!$A$8:$A$101,0)) -> 32988152 | E12: =INDEX(Модель!$G$8:$G$101,MATCH($A12,Модель!$A$8:$A$101,0)) -> 32451852 | F12: =INDEX(Модель!$H$8:$H$101,MATCH($A12,Модель!$A$8:$A$101,0)) -> 1.0909941e+08 | G12: =IF($F$12<>0,F12/$F$12,0) -> 1
A13: C1 | B13: Поддержка клиентов | C13: =INDEX(Модель!$E$8:$E$101,MATCH($A13,Модель!$A$8:$A$101,0)) -> 2535625 | D13: =INDEX(Модель!$F$8:$F$101,MATCH($A13,Модель!$A$8:$A$101,0)) -> 679950 | E13: =INDEX(Модель!$G$8:$G$101,MATCH($A13,Модель!$A$8:$A$101,0)) -> 144720 | F13: =INDEX(Модель!$H$8:$H$101,MATCH($A13,Модель!$A$8:$A$101,0)) -> 3360295 | G13: =IF($F$12<>0,F13/$F$12,0) -> 0.030800304
A14: C2 | B14: Онбординг и KYC | C14: =INDEX(Модель!$E$8:$E$101,MATCH($A14,Модель!$A$8:$A$101,0)) -> 1170000 | D14: =INDEX(Модель!$F$8:$F$101,MATCH($A14,Модель!$A$8:$A$101,0)) -> 54000 | E14: =INDEX(Модель!$G$8:$G$101,MATCH($A14,Модель!$A$8:$A$101,0)) -> 186000 | F14: =INDEX(Модель!$H$8:$H$101,MATCH($A14,Модель!$A$8:$A$101,0)) -> 1410000 | G14: =IF($F$12<>0,F14/$F$12,0) -> 0.012923993
A15: C3 | B15: Бэк-офис: ручные операции | C15: =INDEX(Модель!$E$8:$E$101,MATCH($A15,Модель!$A$8:$A$101,0)) -> 912825 | D15: =INDEX(Модель!$F$8:$F$101,MATCH($A15,Модель!$A$8:$A$101,0)) -> 566625 | E15: =INDEX(Модель!$G$8:$G$101,MATCH($A15,Модель!$A$8:$A$101,0)) -> 603000 | F15: =INDEX(Модель!$H$8:$H$101,MATCH($A15,Модель!$A$8:$A$101,0)) -> 2082450 | G15: =IF($F$12<>0,F15/$F$12,0) -> 0.019087638
A16: C4 | B16: Персональные менеджеры и покрытие | C16: =INDEX(Модель!$E$8:$E$101,MATCH($A16,Модель!$A$8:$A$101,0)) -> 0 | D16: =INDEX(Модель!$F$8:$F$101,MATCH($A16,Модель!$A$8:$A$101,0)) -> 6044000 | E16: =INDEX(Модель!$G$8:$G$101,MATCH($A16,Модель!$A$8:$A$101,0)) -> 4020000 | F16: =INDEX(Модель!$H$8:$H$101,MATCH($A16,Модель!$A$8:$A$101,0)) -> 10064000 | G16: =IF($F$12<>0,F16/$F$12,0) -> 0.092246145
... A22: CM | B22: МД — маржинальный доход | C22: =INDEX(Модель!$E$8:$E$101,MATCH($A22,Модель!$A$8:$A$101,0)) -> 31786706 | D22: =INDEX(Модель!$F$8:$F$101,MATCH($A22,Модель!$A$8:$A$101,0)) -> 23410277 | E22: =INDEX(Модель!$G$8:$G$101,MATCH($A22,Модель!$A$8:$A$101,0)) -> 26356132 | F22: =INDEX(Модель!$H$8:$H$101,MATCH($A22,Модель!$A$8:$A$101,0)) -> 81553114 | G22: =IF($F$12<>0,F22/$F$12,0) -> 0.74751197
A24: Код | B24: Ключевые показатели | C24: Масс-розница | D24: Состоятельные | E24: Институционалы и корп. | F24: Итого
A25: N_AVG | B25: Фондированные клиенты, среднее за период | C25: =INDEX(Модель!$E$8:$E$101,MATCH($A25,Модель!$A$8:$A$101,0)) -> 507125 | D25: =INDEX(Модель!$F$8:$F$101,MATCH($A25,Модель!$A$8:$A$101,0)) -> 15110 | E25: =INDEX(Модель!$G$8:$G$101,MATCH($A25,Модель!$A$8:$A$101,0)) -> 402 | F25: =INDEX(Модель!$H$8:$H$101,MATCH($A25,Модель!$A$8:$A$101,0)) -> 522637
A26: NEW | B26: Новые фондированные клиенты | C26: =INDEX(Модель!$E$8:$E$101,MATCH($A26,Модель!$A$8:$A$101,0)) -> 74250 | D26: =INDEX(Модель!$F$8:$F$101,MATCH($A26,Модель!$A$8:$A$101,0)) -> 1120 | E26: =INDEX(Модель!$G$8:$G$101,MATCH($A26,Модель!$A$8:$A$101,0)) -> 36 | F26: =INDEX(Модель!$H$8:$H$101,MATCH($A26,Модель!$A$8:$A$101,0)) -> 75406
A27: ACTIVE | B27: Активные клиенты (среднемесячно) | C27: =INDEX(Модель!$E$8:$E$101,MATCH($A27,Модель!$A$8:$A$101,0)) -> 177493.75 | D27: =INDEX(Модель!$F$8:$F$101,MATCH($A27,Модель!$A$8:$A$101,0)) -> 8310.5 | E27: =INDEX(Модель!$G$8:$G$101,MATCH($A27,Модель!$A$8:$A$101,0)) -> 321.6 | F27: =INDEX(Модель!$H$8:$H$101,MATCH($A27,Модель!$A$8:$A$101,0)) -> 186125.85
A28: AUC | B28: Активы клиентов, среднее за период | C28: =INDEX(Модель!$E$8:$E$101,MATCH($A28,Модель!$A$8:$A$101,0)) -> 4057000000 | D28: =INDEX(Модель!$F$8:$F$101,MATCH($A28,Модель!$A$8:$A$101,0)) -> 3022000000 | E28: =INDEX(Модель!$G$8:$G$101,MATCH($A28,Модель!$A$8:$A$101,0)) -> 10050000000 | F28: =INDEX(Модель!$H$8:$H$101,MATCH($A28,Модель!$A$8:$A$101,0)) -> 17129000000
A29: TURN | B29: Оборот клиентов за период | C29: =INDEX(Модель!$E$8:$E$101,MATCH($A29,Модель!$A$8:$A$101,0)) -> 10223640000 | D29: =INDEX(Модель!$F$8:$F$101,MATCH($A29,Модель!$A$8:$A$101,0)) -> 5235615000 | E29: =INDEX(Модель!$G$8:$G$101,MATCH($A29,Модель!$A$8:$A$101,0)) -> 50169600000 | F29: =INDEX(Модель!$H$8:$H$101,MATCH($A29,Модель!$A$8:$A$101,0)) -> 65628855000
A30: MPORT | B30: Маржинальный портфель, среднее за период | C30: =INDEX(Модель!$E$8:$E$101,MATCH($A30,Модель!$A$8:$A$101,0)) -> 202850000 | D30: =INDEX(Модель!$F$8:$F$101,MATCH($A30,Модель!$A$8:$A$101,0)) -> 226650000 | E30: =INDEX(Модель!$G$8:$G$101,MATCH($A30,Модель!$A$8:$A$101,0)) -> 402000000 | F30: =INDEX(Модель!$H$8:$H$101,MATCH($A30,Модель!$A$8:$A$101,0)) -> 831500000
A31: ARPU | B31: Чистая выручка на фондированного клиента | C31: =INDEX(Модель!$E$8:$E$101,MATCH($A31,Модель!$A$8:$A$101,0)) -> 86.092 | D31: =INDEX(Модель!$F$8:$F$101,MATCH($A31,Модель!$A$8:$A$101,0)) -> 2183.2 | E31: =INDEX(Модель!$G$8:$G$101,MATCH($A31,Модель!$A$8:$A$101,0)) -> 80726 | F31: =INDEX(Модель!$H$8:$H$101,MATCH($A31,Модель!$A$8:$A$101,0)) -> 208.74796
A32: YIELD | B32: Доходность активов клиентов | C32: =INDEX(Модель!$E$8:$E$101,MATCH($A32,Модель!$A$8:$A$101,0)) -> 107.615 | D32: =INDEX(Модель!$F$8:$F$101,MATCH($A32,Модель!$A$8:$A$101,0)) -> 109.16 | E32: =INDEX(Модель!$G$8:$G$101,MATCH($A32,Модель!$A$8:$A$101,0)) -> 32.2904 | F32: =INDEX(Модель!$H$8:$H$101,MATCH($A32,Модель!$A$8:$A$101,0)) -> 63.692807
A33: CM_MARGIN | B33: Маржинальность (МД ÷ ЧВ) | C33: =INDEX(Модель!$E$8:$E$101,MATCH($A33,Модель!$A$8:$A$101,0)) -> 0.72806089 | D33: =INDEX(Модель!$F$8:$F$101,MATCH($A33,Модель!$A$8:$A$101,0)) -> 0.70965712 | E33: =INDEX(Модель!$G$8:$G$101,MATCH($A33,Модель!$A$8:$A$101,0)) -> 0.81216111 | F33: =INDEX(Модель!$H$8:$H$101,MATCH($A33,Модель!$A$8:$A$101,0)) -> 0.74751197
A34: CM_PC | B34: МД на фондированного клиента | C34: =INDEX(Модель!$E$8:$E$101,MATCH($A34,Модель!$A$8:$A$101,0)) -> 62.680218 | D34: =INDEX(Модель!$F$8:$F$101,MATCH($A34,Модель!$A$8:$A$101,0)) -> 1549.3234 | E34: =INDEX(Модель!$G$8:$G$101,MATCH($A34,Модель!$A$8:$A$101,0)) -> 65562.517 | F34: =INDEX(Модель!$H$8:$H$101,MATCH($A34,Модель!$A$8:$A$101,0)) -> 156.0416
A35: LTV | B35: LTV — вклад клиента за срок жизни | C35: =INDEX(Модель!$E$8:$E$101,MATCH($A35,Модель!$A$8:$A$101,0)) -> 619.94422 | D35: =INDEX(Модель!$F$8:$F$101,MATCH($A35,Модель!$A$8:$A$101,0)) -> 27675.135 | E35: =INDEX(Модель!$G$8:$G$101,MATCH($A35,Модель!$A$8:$A$101,0)) -> 836322.51 | F35: =INDEX(Модель!$H$8:$H$101,MATCH($A35,Модель!$A$8:$A$101,0)) -> 1451.9604
A36: LTV_CAC | B36: LTV ÷ CAC | C36: =INDEX(Модель!$E$8:$E$101,MATCH($A36,Модель!$A$8:$A$101,0)) -> 7.7493027 | D36: =INDEX(Модель!$F$8:$F$101,MATCH($A36,Модель!$A$8:$A$101,0)) -> 18.45009 | E36: =INDEX(Модель!$G$8:$G$101,MATCH($A36,Модель!$A$8:$A$101,0)) -> 55.754834 | F36: =INDEX(Модель!$H$8:$H$101,MATCH($A36,Модель!$A$8:$A$101,0)) -> 13.417466
... A38: RATE_SHARE | B38: Доля ЧВ, зависящая от процентных ставок | C38: =INDEX(Модель!$E$8:$E$101,MATCH($A38,Модель!$A$8:$A$101,0)) -> 0.51108117 | D38: =INDEX(Модель!$F$8:$F$101,MATCH($A38,Модель!$A$8:$A$101,0)) -> 0.35269329 | E38: =INDEX(Модель!$G$8:$G$101,MATCH($A38,Модель!$A$8:$A$101,0)) -> 0.34065852 | F38: =INDEX(Модель!$H$8:$H$101,MATCH($A38,Модель!$A$8:$A$101,0)) -> 0.41249719
A40: Код | B40: Долгосрочный ориентир (горизонт 3: база = NEW ÷ CHURN) | C40: Масс-розница | D40: Состоятельные | E40: Институционалы и корп. | F40: Итого
A41: N_AVG | B41: Фондированные клиенты, среднее за период | C41: =INDEX(Модель!$J$16:$JA$16,MATCH("MR|BASE|3",Модель!$J$6:$JA$6,0)) -> 618750 | D41: =INDEX(Модель!$J$16:$JA$16,MATCH("AF|BASE|3",Модель!$J$6:$JA$6,0)) -> 18666.667 | E41: =INDEX(Модель!$J$16:$JA$16,MATCH("IC|BASE|3",Модель!$J$6:$JA$6,0)) -> 450 | F41: =SUM(C41:E41) -> 637866.67
A42: NR | B42: ЧВ — чистая выручка | C42: =INDEX(Модель!$J$65:$JA$65,MATCH("MR|BASE|3",Модель!$J$6:$JA$6,0)) -> 53269425 | D42: =INDEX(Модель!$J$65:$JA$65,MATCH("AF|BASE|3",Модель!$J$6:$JA$6,0)) -> 40753067 | E42: =INDEX(Модель!$J$65:$JA$65,MATCH("IC|BASE|3",Модель!$J$6:$JA$6,0)) -> 36326700 | F42: =SUM(C42:E42) -> 1.3034919e+08
A43: CM | B43: МД — маржинальный доход | C43: =INDEX(Модель!$J$91:$JA$91,MATCH("MR|BASE|3",Модель!$J$6:$JA$6,0)) -> 40414425 | D43: =INDEX(Модель!$J$91:$JA$91,MATCH("AF|BASE|3",Модель!$J$6:$JA$6,0)) -> 29352400 | E43: =INDEX(Модель!$J$91:$JA$91,MATCH("IC|BASE|3",Модель!$J$6:$JA$6,0)) -> 29613700 | F43: =SUM(C43:E43) -> 99380525
A45: Ранг | B45: Топ-10 объёмных и затратных драйверов: ценность улучшения на 1% | C45: Код | D45: ΔМД в год, долгосрочно | E45: ΔМД, год 1 | F45: Тип рычага | G45: Управляемость
A46: 1 | B46: =INDEX(Чувствительность!$B$5:$B$45,MATCH(LARGE(Чувствительность!$X$5:$X$45,1),Чувствительность!$X$5:$X$45,0)) -> Годовой отток фондированных клиентов (вывели активы ниже порога или закрыли счёт) | C46: =INDEX(Чувствительность!$A$5:$A$45,MATCH(LARGE(Чувствительность!$X$5:$X$45,1),Чувствительность!$X$5:$X$45,0)) -> CHURN | D46: =INDEX(Чувствительность!$Q$5:$Q$45,MATCH(LARGE(Чувствительность!$X$5:$X$45,1),Чувствительность!$X$5:$X$45,0)) -> 1106571 | E46: =INDEX(Чувствительность!$M$5:$M$45,MATCH(LARGE(Чувствительность!$X$5:$X$45,1),Чувствительность!$X$5:$X$45,0)) -> 41564.31 | F46: =INDEX(Чувствительность!$F$5:$F$45,MATCH(LARGE(Чувствительность!$X$5:$X$45,1),Чувствительность!$X$5:$X$45,0)) -> Объёмный | G46: =INDEX(Чувствительность!$E$5:$E$45,MATCH(LARGE(Чувствительность!$X$5:$X$45,1),Чувствительность!$X$5:$X$45,0)) -> Управляемый
A47: 2 | B47: =INDEX(Чувствительность!$B$5:$B$45,MATCH(LARGE(Чувствительность!$X$5:$X$45,2),Чувствительность!$X$5:$X$45,0)) -> Конверсия: открытый счёт → фондированный (первое пополнение) | C47: =INDEX(Чувствительность!$A$5:$A$45,MATCH(LARGE(Чувствительность!$X$5:$X$45,2),Чувствительность!$X$5:$X$45,0)) -> CR_FUND | D47: =INDEX(Чувствительность!$Q$5:$Q$45,MATCH(LARGE(Чувствительность!$X$5:$X$45,2),Чувствительность!$X$5:$X$45,0)) -> 1013905.3 | E47: =INDEX(Чувствительность!$M$5:$M$45,MATCH(LARGE(Чувствительность!$X$5:$X$45,2),Чувствительность!$X$5:$X$45,0)) -> -31333.545 | F47: =INDEX(Чувствительность!$F$5:$F$45,MATCH(LARGE(Чувствительность!$X$5:$X$45,2),Чувствительность!$X$5:$X$45,0)) -> Объёмный | G47: =INDEX(Чувствительность!$E$5:$E$45,MATCH(LARGE(Чувствительность!$X$5:$X$45,2),Чувствительность!$X$5:$X$45,0)) -> Управляемый
A48: 3 | B48: =INDEX(Чувствительность!$B$5:$B$45,MATCH(LARGE(Чувствительность!$X$5:$X$45,3),Чувствительность!$X$5:$X$45,0)) -> Конверсия: заявка → открытый счёт (KYC пройден; ИК — договор подписан) | C48: =INDEX(Чувствительность!$A$5:$A$45,MATCH(LARGE(Чувствительность!$X$5:$X$45,3),Чувствительность!$X$5:$X$45,0)) -> CR_OPEN | D48: =INDEX(Чувствительность!$Q$5:$Q$45,MATCH(LARGE(Чувствительность!$X$5:$X$45,3),Чувствительность!$X$5:$X$45,0)) -> 1013905.3 | E48: =INDEX(Чувствительность!$M$5:$M$45,MATCH(LARGE(Чувствительность!$X$5:$X$45,3),Чувствительность!$X$5:$X$45,0)) -> -31333.545 | F48: =INDEX(Чувствительность!$F$5:$F$45,MATCH(LARGE(Чувствительность!$X$5:$X$45,3),Чувствительность!$X$5:$X$45,0)) -> Объёмный | G48: =INDEX(Чувствительность!$E$5:$E$45,MATCH(LARGE(Чувствительность!$X$5:$X$45,3),Чувствительность!$X$5:$X$45,0)) -> Управляемый
A49: 4 | B49: =INDEX(Чувствительность!$B$5:$B$45,MATCH(LARGE(Чувствительность!$X$5:$X$45,4),Чувствительность!$X$5:$X$45,0)) -> Заявки на открытие счёта за период (ИК — потенциальные клиенты в воронке продаж) | C49: =INDEX(Чувствительность!$A$5:$A$45,MATCH(LARGE(Чувствительность!$X$5:$X$45,4),Чувствительность!$X$5:$X$45,0)) -> LEADS | D49: =INDEX(Чувствительность!$Q$5:$Q$45,MATCH(LARGE(Чувствительность!$X$5:$X$45,4),Чувствительность!$X$5:$X$45,0)) -> 999805.25 | E49: =INDEX(Чувствительность!$M$5:$M$45,MATCH(LARGE(Чувствительность!$X$5:$X$45,4),Чувствительность!$X$5:$X$45,0)) -> -45433.545 | F49: =INDEX(Чувствительность!$F$5:$F$45,MATCH(LARGE(Чувствительность!$X$5:$X$45,4),Чувствительность!$X$5:$X$45,0)) -> Объёмный | G49: =INDEX(Чувствительность!$E$5:$E$45,MATCH(LARGE(Чувствительность!$X$5:$X$45,4),Чувствительность!$X$5:$X$45,0)) -> Управляемый
...

Sheet Дерево
A1: Дерево метрик: от маржинального дохода к драйверам
A2: Каждый узел — формула от дочерних. Значения — базовый расчёт с листа «Модель».
A4: Уровень | B4: Код | C4: Метрика | D4: Формула | E4: Ед. | F4: Масс-розница | G4: Состоятельные | H4: Институционалы и корп. | I4: Итого | J4: Тип
A5: 0 | B5: CM | C5: МД — маржинальный доход | D5: ЧВ − ЗО − ЗП − ПТ | E5: у.е. | F5: =INDEX(Модель!$E$8:$E$101,MATCH($B5,Модель!$A$8:$A$101,0)) -> 31786706 | G5: =INDEX(Модель!$F$8:$F$101,MATCH($B5,Модель!$A$8:$A$101,0)) -> 23410277 | H5: =INDEX(Модель!$G$8:$G$101,MATCH($B5,Модель!$A$8:$A$101,0)) -> 26356132 | I5: =INDEX(Модель!$H$8:$H$101,MATCH($B5,Модель!$A$8:$A$101,0)) -> 81553114 | J5: Расчёт
A6: 1 | B6: NR | C6: ЧВ — чистая выручка | D6: R1 + R2 + R3 + R4 + R5 + R6 + R7 | E6: у.е. | F6: =INDEX(Модель!$E$8:$E$101,MATCH($B6,Модель!$A$8:$A$101,0)) -> 43659406 | G6: =INDEX(Модель!$F$8:$F$101,MATCH($B6,Модель!$A$8:$A$101,0)) -> 32988152 | H6: =INDEX(Модель!$G$8:$G$101,MATCH($B6,Модель!$A$8:$A$101,0)) -> 32451852 | I6: =INDEX(Модель!$H$8:$H$101,MATCH($B6,Модель!$A$8:$A$101,0)) -> 1.0909941e+08 | J6: Расчёт
A7: 2 | B7: R1 | C7: Торговые комиссии (нетто) | D7: TURN × (TAKE − EXEC) | E7: у.е. | F7: =INDEX(Модель!$E$8:$E$101,MATCH($B7,Модель!$A$8:$A$101,0)) -> 12268368 | G7: =INDEX(Модель!$F$8:$F$101,MATCH($B7,Модель!$A$8:$A$101,0)) -> 4188492 | H7: =INDEX(Модель!$G$8:$G$101,MATCH($B7,Модель!$A$8:$A$101,0)) -> 6020352 | I7: =INDEX(Модель!$H$8:$H$101,MATCH($B7,Модель!$A$8:$A$101,0)) -> 22477212 | J7: Расчёт
A8: 3 | B8: TURN | C8: Оборот клиентов за период | D8: ACTIVE × TPA × 12 × TICKET | E8: у.е. | F8: =INDEX(Модель!$E$8:$E$101,MATCH($B8,Модель!$A$8:$A$101,0)) -> 10223640000 | G8: =INDEX(Модель!$F$8:$F$101,MATCH($B8,Модель!$A$8:$A$101,0)) -> 5235615000 | H8: =INDEX(Модель!$G$8:$G$101,MATCH($B8,Модель!$A$8:$A$101,0)) -> 50169600000 | I8: =INDEX(Модель!$H$8:$H$101,MATCH($B8,Модель!$A$8:$A$101,0)) -> 65628855000 | J8: Расчёт
A9: 4 | B9: ACTIVE | C9: Активные клиенты (среднемесячно) | D9: N_AVG × ACT | E9: чел. | F9: =INDEX(Модель!$E$8:$E$101,MATCH($B9,Модель!$A$8:$A$101,0)) -> 177493.75 | G9: =INDEX(Модель!$F$8:$F$101,MATCH($B9,Модель!$A$8:$A$101,0)) -> 8310.5 | H9: =INDEX(Модель!$G$8:$G$101,MATCH($B9,Модель!$A$8:$A$101,0)) -> 321.6 | I9: =INDEX(Модель!$H$8:$H$101,MATCH($B9,Модель!$A$8:$A$101,0)) -> 186125.85 | J9: Расчёт
A10: 4 | B10: TPA | C10: Сделок в месяц на активного клиента | D10: Вводная | E10: шт./клиент | F10: =INDEX(Модель!$E$8:$E$101,MATCH($B10,Модель!$A$8:$A$101,0)) -> 6 | G10: =INDEX(Модель!$F$8:$F$101,MATCH($B10,Модель!$A$8:$A$101,0)) -> 3.5 | H10: =INDEX(Модель!$G$8:$G$101,MATCH($B10,Модель!$A$8:$A$101,0)) -> 130 | J10: Вводная: объёмный
A11: 4 | B11: TICKET | C11: Средний объём сделки | D11: Вводная | E11: у.е. | F11: =INDEX(Модель!$E$8:$E$101,MATCH($B11,Модель!$A$8:$A$101,0)) -> 800 | G11: =INDEX(Модель!$F$8:$F$101,MATCH($B11,Модель!$A$8:$A$101,0)) -> 15000 | H11: =INDEX(Модель!$G$8:$G$101,MATCH($B11,Модель!$A$8:$A$101,0)) -> 100000 | J11: Вводная: объёмный
A12: 3 | B12: TAKE | C12: Комиссия брокера, % от оборота (эффективная, с учётом тарифов и скидок) | D12: Вводная | E12: % | F12: =INDEX(Модель!$E$8:$E$101,MATCH($B12,Модель!$A$8:$A$101,0)) -> 0.0015 | G12: =INDEX(Модель!$F$8:$F$101,MATCH($B12,Модель!$A$8:$A$101,0)) -> 0.001 | H12: =INDEX(Модель!$G$8:$G$101,MATCH($B12,Модель!$A$8:$A$101,0)) -> 0.0002 | J12: Вводная: ценовой
A13: 3 | B13: EXEC | C13: Затраты на исполнение (биржевые, клиринговые, депозитарные сборы, вышестоящий брокер), % от оборота | D13: Вводная | E13: % | F13: =INDEX(Модель!$E$8:$E$101,MATCH($B13,Модель!$A$8:$A$101,0)) -> 0.0003 | G13: =INDEX(Модель!$F$8:$F$101,MATCH($B13,Модель!$A$8:$A$101,0)) -> 0.0002 | H13: =INDEX(Модель!$G$8:$G$101,MATCH($B13,Модель!$A$8:$A$101,0)) -> 8e-05 | J13: Вводная: затратный
A14: 2 | B14: R2 | C14: Маржинальное кредитование (нетто) | D14: MPORT × ((MRG_RATE + RATE_SHIFT × PT_MRG) − (FUND_RATE + RATE_SHIFT)) | E14: у.е. | F14: =INDEX(Модель!$E$8:$E$101,MATCH($B14,Модель!$A$8:$A$101,0)) -> 10142500 | G14: =INDEX(Модель!$F$8:$F$101,MATCH($B14,Модель!$A$8:$A$101,0)) -> 6799500 | H14: =INDEX(Модель!$G$8:$G$101,MATCH($B14,Модель!$A$8:$A$101,0)) -> 6030000 | I14: =INDEX(Модель!$H$8:$H$101,MATCH($B14,Модель!$A$8:$A$101,0)) -> 22972000 | J14: Расчёт
A15: 3 | B15: MPORT | C15: Маржинальный портфель, среднее за период | D15: N_AVG × MRG_PEN × MRG_DEBT | E15: у.е. | F15: =INDEX(Модель!$E$8:$E$101,MATCH($B15,Модель!$A$8:$A$101,0)) -> 202850000 | G15: =INDEX(Модель!$F$8:$F$101,MATCH($B15,Модель!$A$8:$A$101,0)) -> 226650000 | H15: =INDEX(Модель!$G$8:$G$101,MATCH($B15,Модель!$A$8:$A$101,0)) -> 402000000 | I15: =INDEX(Модель!$H$8:$H$101,MATCH($B15,Модель!$A$8:$A$101,0)) -> 831500000 | J15: Расчёт
A16: 4 | B16: MRG_PEN | C16: Проникновение маржинальной торговли: доля фондированных клиентов с задолженностью | D16: Вводная | E16: % | F16: =INDEX(Модель!$E$8:$E$101,MATCH($B16,Модель!$A$8:$A$101,0)) -> 0.05 | G16: =INDEX(Модель!$F$8:$F$101,MATCH($B16,Модель!$A$8:$A$101,0)) -> 0.1 | H16: =INDEX(Модель!$G$8:$G$101,MATCH($B16,Модель!$A$8:$A$101,0)) -> 0.2 | J16: Вводная: объёмный
A17: 4 | B17: MRG_DEBT | C17: Средняя задолженность маржинального клиента | D17: Вводная | E17: у.е. | F17: =INDEX(Модель!$E$8:$E$101,MATCH($B17,Модель!$A$8:$A$101,0)) -> 8000 | G17: =INDEX(Модель!$F$8:$F$101,MATCH($B17,Модель!$A$8:$A$101,0)) -> 150000 | H17: =INDEX(Модель!$G$8:$G$101,MATCH($B17,Модель!$A$8:$A$101,0)) -> 5000000 | J17: Вводная: объёмный
A18: 3 | B18: MRG_RATE | C18: Ставка для клиента по маржинальному кредиту (деньги и ценные бумаги) | D18: Вводная | E18: % | F18: =INDEX(Модель!$E$8:$E$101,MATCH($B18,Модель!$A$8:$A$101,0)) -> 0.12 | G18: =INDEX(Модель!$F$8:$F$101,MATCH($B18,Модель!$A$8:$A$101,0)) -> 0.1 | H18: =INDEX(Модель!$G$8:$G$101,MATCH($B18,Модель!$A$8:$A$101,0)) -> 0.08 | J18: Вводная: ценовой
A19: 3 | B19: FUND_RATE | C19: Стоимость фондирования маржинального портфеля | D19: Вводная | E19: % | F19: =INDEX(Модель!$E$8:$E$101,MATCH($B19,Модель!$A$8:$A$101,0)) -> 0.07 | G19: =INDEX(Модель!$F$8:$F$101,MATCH($B19,Модель!$A$8:$A$101,0)) -> 0.07 | H19: =INDEX(Модель!$G$8:$G$101,MATCH($B19,Модель!$A$8:$A$101,0)) -> 0.065 | J19: Вводная: внешний
A20: 2 | B20: R3 | C20: Доход на свободные остатки (нетто) | D20: CASHBAL × ((FLOAT_Y + RATE_SHIFT) − max(0; FLOAT_P + RATE_SHIFT × PT_FLOAT)) | E20: у.е. | F20: =INDEX(Модель!$E$8:$E$101,MATCH($B20,Модель!$A$8:$A$101,0)) -> 12171000 | G20: =INDEX(Модель!$F$8:$F$101,MATCH($B20,Модель!$A$8:$A$101,0)) -> 4835200 | H20: =INDEX(Модель!$G$8:$G$101,MATCH($B20,Модель!$A$8:$A$101,0)) -> 5025000 | I20: =INDEX(Модель!$H$8:$H$101,MATCH($B20,Модель!$A$8:$A$101,0)) -> 22031200 | J20: Расчёт
A21: 3 | B21: CASHBAL | C21: Свободные денежные остатки клиентов | D21: AUC × CASH | E21: у.е. | F21: =INDEX(Модель!$E$8:$E$101,MATCH($B21,Модель!$A$8:$A$101,0)) -> 486840000 | G21: =INDEX(Модель!$F$8:$F$101,MATCH($B21,Модель!$A$8:$A$101,0)) -> 241760000 | H21: =INDEX(Модель!$G$8:$G$101,MATCH($B21,Модель!$A$8:$A$101,0)) -> 502500000 | I21: =INDEX(Модель!$H$8:$H$101,MATCH($B21,Модель!$A$8:$A$101,0)) -> 1231100000 | J21: Расчёт
A22: 4 | B22: AUC | C22: Активы клиентов, среднее за период | D22: N_AVG × AUC_PC | E22: у.е. | F22: =INDEX(Модель!$E$8:$E$101,MATCH($B22,Модель!$A$8:$A$101,0)) -> 4057000000 | G22: =INDEX(Модель!$F$8:$F$101,MATCH($B22,Модель!$A$8:$A$101,0)) -> 3022000000 | H22: =INDEX(Модель!$G$8:$G$101,MATCH($B22,Модель!$A$8:$A$101,0)) -> 10050000000 | I22: =INDEX(Модель!$H$8:$H$101,MATCH($B22,Модель!$A$8:$A$101,0)) -> 17129000000 | J22: Расчёт
A23: 5 | B23: AUC_PC | C23: Средние активы на фондированного клиента | D23: Вводная | E23: у.е. | F23: =INDEX(Модель!$E$8:$E$101,MATCH($B23,Модель!$A$8:$A$101,0)) -> 8000 | G23: =INDEX(Модель!$F$8:$F$101,MATCH($B23,Модель!$A$8:$A$101,0)) -> 200000 | H23: =INDEX(Модель!$G$8:$G$101,MATCH($B23,Модель!$A$8:$A$101,0)) -> 25000000 | J23: Вводная: объёмный
A24: 4 | B24: CASH | C24: Доля свободных денежных средств в активах клиентов | D24: Вводная | E24: % | F24: =INDEX(Модель!$E$8:$E$101,MATCH($B24,Модель!$A$8:$A$101,0)) -> 0.12 | G24: =INDEX(Модель!$F$8:$F$101,MATCH($B24,Модель!$A$8:$A$101,0)) -> 0.08 | H24: =INDEX(Модель!$G$8:$G$101,MATCH($B24,Модель!$A$8:$A$101,0)) -> 0.05 | J24: Вводная: объёмный
A25: 3 | B25: FLOAT_Y | C25: Доходность размещения свободных остатков клиентов | D25: Вводная | E25: % | F25: =INDEX(Модель!$E$8:$E$101,MATCH($B25,Модель!$A$8:$A$101,0)) -> 0.05 | G25: =INDEX(Модель!$F$8:$F$101,MATCH($B25,Модель!$A$8:$A$101,0)) -> 0.05 | H25: =INDEX(Модель!$G$8:$G$101,MATCH($B25,Модель!$A$8:$A$101,0)) -> 0.05 | J25: Вводная: внешний
A26: 3 | B26: FLOAT_P | C26: Ставка, выплачиваемая клиентам на свободные остатки | D26: Вводная | E26: % | F26: =INDEX(Модель!$E$8:$E$101,MATCH($B26,Модель!$A$8:$A$101,0)) -> 0.02 | G26: =INDEX(Модель!$F$8:$F$101,MATCH($B26,Модель!$A$8:$A$101,0)) -> 0.025 | H26: =INDEX(Модель!$G$8:$G$101,MATCH($B26,Модель!$A$8:$A$101,0)) -> 0.035 | J26: Вводная: ценовой
A27: 2 | B27: R4 | C27: Конвертация валют | D27: FXVOLUME × FX_SPREAD | E27: у.е. | F27: =INDEX(Модель!$E$8:$E$101,MATCH($B27,Модель!$A$8:$A$101,0)) -> 3803437.5 | G27: =INDEX(Модель!$F$8:$F$101,MATCH($B27,Модель!$A$8:$A$101,0)) -> 2266500 | H27: =INDEX(Модель!$G$8:$G$101,MATCH($B27,Модель!$A$8:$A$101,0)) -> 804000 | I27: =INDEX(Модель!$H$8:$H$101,MATCH($B27,Модель!$A$8:$A$101,0)) -> 6873937.5 | J27: Расчёт
A28: 3 | B28: FXVOLUME | C28: Объём конвертаций за период | D28: N_AVG × FX_PEN × FX_VOL | E28: у.е. | F28: =INDEX(Модель!$E$8:$E$101,MATCH($B28,Модель!$A$8:$A$101,0)) -> 760687500 | G28: =INDEX(Модель!$F$8:$F$101,MATCH($B28,Модель!$A$8:$A$101,0)) -> 755500000 | H28: =INDEX(Модель!$G$8:$G$101,MATCH($B28,Модель!$A$8:$A$101,0)) -> 1608000000 | I28: =INDEX(Модель!$H$8:$H$101,MATCH($B28,Модель!$A$8:$A$101,0)) -> 3124187500 | J28: Расчёт
A29: 4 | B29: FX_PEN | C29: Доля фондированных клиентов, совершающих конвертации | D29: Вводная | E29: % | F29: =INDEX(Модель!$E$8:$E$101,MATCH($B29,Модель!$A$8:$A$101,0)) -> 0.3 | G29: =INDEX(Модель!$F$8:$F$101,MATCH($B29,Модель!$A$8:$A$101,0)) -> 0.5 | H29: =INDEX(Модель!$G$8:$G$101,MATCH($B29,Модель!$A$8:$A$101,0)) -> 0.4 | J29: Вводная: объёмный
A30: 4 | B30: FX_VOL | C30: Объём конвертаций на конвертирующего клиента в год | D30: Вводная | E30: у.е. | F30: =INDEX(Модель!$E$8:$E$101,MATCH($B30,Модель!$A$8:$A$101,0)) -> 5000 | G30: =INDEX(Модель!$F$8:$F$101,MATCH($B30,Модель!$A$8:$A$101,0)) -> 100000 | H30: =INDEX(Модель!$G$8:$G$101,MATCH($B30,Модель!$A$8:$A$101,0)) -> 10000000 | J30: Вводная: объёмный
A31: 3 | B31: FX_SPREAD | C31: Комиссия и спред за конвертацию, % от объёма | D31: Вводная | E31: % | F31: =INDEX(Модель!$E$8:$E$101,MATCH($B31,Модель!$A$8:$A$101,0)) -> 0.005 | G31: =INDEX(Модель!$F$8:$F$101,MATCH($B31,Модель!$A$8:$A$101,0)) -> 0.003 | H31: =INDEX(Модель!$G$8:$G$101,MATCH($B31,Модель!$A$8:$A$101,0)) -> 0.0005 | J31: Вводная: ценовой
A32: 2 | B32: R5 | C32: Размещения и продукты | D32: PRDVOLUME × PRD_FEE | E32: у.е. | F32: =INDEX(Модель!$E$8:$E$101,MATCH($B32,Модель!$A$8:$A$101,0)) -> 1217100 | G32: =INDEX(Модель!$F$8:$F$101,MATCH($B32,Модель!$A$8:$A$101,0)) -> 5076960 | H32: =INDEX(Модель!$G$8:$G$101,MATCH($B32,Модель!$A$8:$A$101,0)) -> 10050000 | I32: =INDEX(Модель!$H$8:$H$101,MATCH($B32,Модель!$A$8:$A$101,0)) -> 16344060 | J32: Расчёт
A33: 3 | B33: PRDVOLUME | C33: Объём продаж продуктов и размещений | D33: N_AVG × PRD_PEN × PRD_VOL | E33: у.е. | F33: =INDEX(Модель!$E$8:$E$101,MATCH($B33,Модель!$A$8:$A$101,0)) -> 121710000 | G33: =INDEX(Модель!$F$8:$F$101,MATCH($B33,Модель!$A$8:$A$101,0)) -> 423080000 | H33: =INDEX(Модель!$G$8:$G$101,MATCH($B33,Модель!$A$8:$A$101,0)) -> 1005000000 | I33: =INDEX(Модель!$H$8:$H$101,MATCH($B33,Модель!$A$8:$A$101,0)) -> 1549790000 | J33: Расчёт
A34: 4 | B34: PRD_PEN | C34: Доля фондированных клиентов, купивших размещения или продукты за год (ИК — доля клиентов-эмитентов, проведших размещение) | D34: Вводная | E34: % | F34: =INDEX(Модель!$E$8:$E$101,MATCH($B34,Модель!$A$8:$A$101,0)) -> 0.08 | G34: =INDEX(Модель!$F$8:$F$101,MATCH($B34,Модель!$A$8:$A$101,0)) -> 0.35 | H34: =INDEX(Модель!$G$8:$G$101,MATCH($B34,Модель!$A$8:$A$101,0)) -> 0.05 | J34: Вводная: объёмный
A35: 4 | B35: PRD_VOL | C35: Средний объём покупок продуктов на клиента в год (ИК — средний объём размещения) | D35: Вводная | E35: у.е. | F35: =INDEX(Модель!$E$8:$E$101,MATCH($B35,Модель!$A$8:$A$101,0)) -> 3000 | G35: =INDEX(Модель!$F$8:$F$101,MATCH($B35,Модель!$A$8:$A$101,0)) -> 80000 | H35: =INDEX(Модель!$G$8:$G$101,MATCH($B35,Модель!$A$8:$A$101,0)) -> 50000000 | J35: Вводная: объёмный
A36: 3 | B36: PRD_FEE | C36: Средняя комиссия или маржа по продуктам и размещениям, % от объёма | D36: Вводная | E36: % | F36: =INDEX(Модель!$E$8:$E$101,MATCH($B36,Модель!$A$8:$A$101,0)) -> 0.01 | G36: =INDEX(Модель!$F$8:$F$101,MATCH($B36,Модель!$A$8:$A$101,0)) -> 0.012 | H36: =INDEX(Модель!$G$8:$G$101,MATCH($B36,Модель!$A$8:$A$101,0)) -> 0.01 | J36: Вводная: ценовой
A37: 2 | B37: R6 | C37: ДУ и консультирование | D37: AUM × AM_FEE | E37: у.е. | F37: =INDEX(Модель!$E$8:$E$101,MATCH($B37,Модель!$A$8:$A$101,0)) -> 811400 | G37: =INDEX(Модель!$F$8:$F$101,MATCH($B37,Модель!$A$8:$A$101,0)) -> 6044000 | H37: =INDEX(Модель!$G$8:$G$101,MATCH($B37,Модель!$A$8:$A$101,0)) -> 1507500 | I37: =INDEX(Модель!$H$8:$H$101,MATCH($B37,Модель!$A$8:$A$101,0)) -> 8362900 | J37: Расчёт
A38: 3 | B38: AUM | C38: Активы в ДУ и на консультировании | D38: AUC × AM_SHARE | E38: у.е. | F38: =INDEX(Модель!$E$8:$E$101,MATCH($B38,Модель!$A$8:$A$101,0)) -> 81140000 | G38: =INDEX(Модель!$F$8:$F$101,MATCH($B38,Модель!$A$8:$A$101,0)) -> 604400000 | H38: =INDEX(Модель!$G$8:$G$101,MATCH($B38,Модель!$A$8:$A$101,0)) -> 502500000 | I38: =INDEX(Модель!$H$8:$H$101,MATCH($B38,Модель!$A$8:$A$101,0)) -> 1188040000 | J38: Расчёт
A39: 4 | B39: AM_SHARE | C39: Доля активов клиентов в ДУ, модельных портфелях и на консультировании | D39: Вводная | E39: % | F39: =INDEX(Модель!$E$8:$E$101,MATCH($B39,Модель!$A$8:$A$101,0)) -> 0.02 | G39: =INDEX(Модель!$F$8:$F$101,MATCH($B39,Модель!$A$8:$A$101,0)) -> 0.2 | H39: =INDEX(Модель!$G$8:$G$101,MATCH($B39,Модель!$A$8:$A$101,0)) -> 0.05 | J39: Вводная: объёмный
A40: 3 | B40: AM_FEE | C40: Комиссия за управление и консультирование, % годовых (вкл. success fee) | D40: Вводная | E40: % | F40: =INDEX(Модель!$E$8:$E$101,MATCH($B40,Модель!$A$8:$A$101,0)) -> 0.01 | G40: =INDEX(Модель!$F$8:$F$101,MATCH($B40,Модель!$A$8:$A$101,0)) -> 0.01 | H40: =INDEX(Модель!$G$8:$G$101,MATCH($B40,Модель!$A$8:$A$101,0)) -> 0.003 | J40: Вводная: ценовой
A41: 2 | B41: R7 | C41: Подписки и сервисные комиссии | D41: SUBS × SUB_PRICE + AUC × CUST_FEE | E41: у.е. | F41: =INDEX(Модель!$E$8:$E$101,MATCH($B41,Модель!$A$8:$A$101,0)) -> 3245600 | G41: =INDEX(Модель!$F$8:$F$101,MATCH($B41,Модель!$A$8:$A$101,0)) -> 3777500 | H41: =INDEX(Модель!$G$8:$G$101,MATCH($B41,Модель!$A$8:$A$101,0)) -> 3015000 | I41: =INDEX(Модель!$H$8:$H$101,MATCH($B41,Модель!$A$8:$A$101,0)) -> 10038100 | J41: Расчёт
...

Sheet Вводные
A1: Вводные модели по сегментам
A2: Синий шрифт на жёлтом фоне — вводные. Значения иллюстративные: замените их фактическими данными. Все суммы — в условных единицах (у.е.) за период (год).
A4: Глобальные параметры
A5: SHOCK | B5: Шаг анализа чувствительности (улучшение драйвера, относительное) | C5: % | D5: 0.01 | L5: 1% — стандарт; модель линейна по каждому драйверу, поэтому эффект +5% = 5 × эффект +1%.
A6: HORIZON | B6: Горизонт оценки для листов «Сводка», «Дерево» и колонок E–H «Модели» | C6: режим | D6: 1 | L6: 1 — год 1: P&L плана, новые и ушедшие клиенты учитываются за полгода; 2 — run-rate на конец года; 3 — долгосрочно: база сходится к NEW ÷ CHURN. Чувствительность всегда считается в режимах 1 и 3.
A7: RATE_SHIFT | B7: Сценарий ставок: сдвиг рыночных ставок к текущим (FLOAT_Y, FUND_RATE) | C7: сдвиг | D7: -0.01 | L7: Решение 07.10.2026: план строится только на сценарии снижения ставок. Величина −1 п.п. — допущение, поменяйте при необходимости.
A8: PT_MRG | B8: Доля сдвига ставок, которая переходит в ставку по марже для клиентов | C8: коэф. | D8: 1 | L8: 1 — ставка по марже следует за рынком полностью, спред по марже сохраняется.
A9: PT_FLOAT | B9: Доля сдвига ставок, которая переходит в ставку клиентам на остатки | C9: коэф. | D9: 0.5 | L9: 0,5 — брокер снижает ставку клиентам вдвое медленнее рынка; спред на остатках сужается.
A11: коды сегментов → | D11: MR | E11: AF | F11: IC
A12: Код | B12: Параметр | C12: Ед. | D12: Масс-розница | E12: Состоятельные | F12: Институционалы и корп. | G12: Направление | H12: Управляемость | I12: Тип рычага | J12: Влияет на | K12: Источник / ориентир | L12: Комментарий
A13: Клиентская база и воронка
A14: N0 | B14: Фондированные клиенты на начало периода | C14: чел. | D14: 500000 | E14: 15000 | F14: 400 | G14: 1 | H14: Состояние | I14: База | J14: Все ветки | K14: Масштаб условный. | L14: Фондированный клиент — активы от ≈$100 в эквиваленте (решение 07.10.2026).
A15: LEADS | B15: Заявки на открытие счёта за период (ИК — потенциальные клиенты в воронке продаж) | C15: шт. | D15: 300000 | E15: 2000 | F15: 120 | G15: 1 | H15: Управляемый | I15: Объёмный | J15: NEW, C2 | K15: Масштаб условный.
A16: CR_OPEN | B16: Конверсия: заявка → открытый счёт (KYC пройден; ИК — договор подписан) | C16: % | D16: 0.45 | E16: 0.7 | F16: 0.4 | G16: 1 | H16: Управляемый | I16: Объёмный | J16: NEW | K16: Futu 2025: пользователь приложения → брокерский счёт 20,4%. Цифровой KYC завершают 60–90% начавших (вендорные данные).
A17: CR_FUND | B17: Конверсия: открытый счёт → фондированный (первое пополнение) | C17: % | D17: 0.55 | E17: 0.8 | F17: 0.75 | G17: 1 | H17: Управляемый | I17: Объёмный | J17: NEW | K17: Futu 2025: счёт → фондированный 56,6%. Регистрация → фондированный: eToro ≈9%, Webull 19–23%.
A18: CHURN | B18: Годовой отток фондированных клиентов (вывели активы ниже порога или закрыли счёт) | C18: % | D18: 0.12 | E18: 0.06 | F18: 0.08 | G18: -1 | H18: Управляемый | I18: Объёмный | J18: CHURNED → N_AVG, LTV | K18: Удержание клиентов в год: Webull и Futu ≈88–92%, Wealthfront 95%, AJ Bell 94,2%, Hargreaves Lansdown 91–92% (2023–2025).
A19: ACT | B19: Доля активных: среднемесячная доля фондированных клиентов с ≥1 операцией (сделка, пополнение, покупка продукта или подписки) | C19: % | D19: 0.35 | E19: 0.55 | F19: 0.8 | G19: 1 | H19: Управляемый | I19: Объёмный | J19: ACTIVE → TURN → R1 | K19: Активность «любая операция» лежит между торговой и заходами в приложение: Мосбиржа 2025 — в среднем месяце торгуют ≈24% непустых счетов [расчёт]; Robinhood — MAU ÷ фондированные ≈47% (2023).
A20: Торговая активность и комиссии
A21: TPA | B21: Сделок в месяц на активного клиента | C21: шт./клиент | D21: 6 | E21: 3.5 | F21: 130 | G21: 1 | H21: Частично | I21: Объёмный | J21: TURN → R1 | K21: Сделок на клиента в год: flatexDEGIRO 23–26, Nordnet ≈25–30 (в модели МР: ACT × TPA × 12 ≈ 25); счёт Schwab ≈75; IBKR ≈160 (2025–2026). | L21: Зависит от волатильности рынка.
A22: TICKET | B22: Средний объём сделки | C22: у.е. | D22: 800 | E22: 15000 | F22: 100000 | G22: 1 | H22: Частично | I22: Объёмный | J22: TURN → R1 | K22: Условно.
A23: TAKE | B23: Комиссия брокера, % от оборота (эффективная, с учётом тарифов и скидок) | C23: % | D23: 0.0015 | E23: 0.001 | F23: 0.0002 | G23: 1 | H23: Управляемый | I23: Ценовой | J23: R1 | K23: Тарифы: Россия 0,3% без абонплаты и 0,018–0,06% на активных тарифах; Казахстан: Freedom 0,085%, Halyk 0,03%. Эффективная ставка зависит от микса тарифов. | L23: Ценовой рычаг: эффект показан при неизменном обороте; учитывать эластичность.
A24: EXEC | B24: Затраты на исполнение (биржевые, клиринговые, депозитарные сборы, вышестоящий брокер), % от оборота | C24: % | D24: 0.0003 | E24: 0.0002 | F24: 8e-05 | G24: -1 | H24: Частично | I24: Затратный | J24: R1 | K24: IBKR 2025: затраты на исполнение и клиринг ≈21% от комиссий.
A25: Активы клиентов и свободные остатки
A26: AUC_PC | B26: Средние активы на фондированного клиента | C26: у.е. | D26: 8000 | E26: 200000 | F26: 25000000 | G26: 1 | H26: Частично | I26: Объёмный | J26: AUC → R3, R6, R7 | K26: Robinhood ≈ $10 тыс. на фондированного [расчёт: ARPU $171 ÷ 173 б.п.]; T-Investments ≈219 тыс. ₽ на клиента (2026); РФ: 2,3 млн ₽ на клиента с активами > 10 тыс. ₽ (ЦБ РФ, Q2 2026). | L26: Управляемая часть — чистый приток (NNA); переоценка — рыночный эффект.
A27: CASH | B27: Доля свободных денежных средств в активах клиентов | C27: % | D27: 0.12 | E27: 0.08 | F27: 0.05 | G27: 1 | H27: Частично | I27: Объёмный | J27: CASHBAL → R3 | K27: Свободные остатки к активам: Robinhood 8,1% (08.2026), Schwab 8,8–9,7%, IBKR 19–21% (2026). | L27: Рост доли кэша повышает R3, но может снижать оборот и продажи продуктов.
A28: FLOAT_Y | B28: Доходность размещения свободных остатков клиентов | C28: % | D28: 0.05 | E28: 0.05 | F28: 0.05 | G28: 1 | H28: Внешний | I28: Внешний | J28: R3 | K28: Внешний фактор: текущая ставка денежного рынка, к ней применяется сценарий RATE_SHIFT. | L28: Определяется ставками денежного рынка и правилами размещения клиентских средств.
A29: FLOAT_P | B29: Ставка, выплачиваемая клиентам на свободные остатки | C29: % | D29: 0.02 | E29: 0.025 | F29: 0.035 | G29: -1 | H29: Управляемый | I29: Ценовой | J29: R3 | K29: Условно: зависит от тарифной политики и конкурентов. | L29: Ценовой рычаг: снижение ставки может вызвать отток остатков.
A30: Маржинальное кредитование
A31: MRG_PEN | B31: Проникновение маржинальной торговли: доля фондированных клиентов с задолженностью | C31: % | D31: 0.05 | E31: 0.1 | F31: 0.2 | G31: 1 | H31: Управляемый | I31: Объёмный | J31: MPORT → R2, C5 | K31: Маржинальный портфель к активам: Robinhood 5,6% (08.2026), IBKR 10,9–11,7%, Schwab ≈1–1,3%. Доля клиентов с маржой публично не раскрывается.
A32: MRG_DEBT | B32: Средняя задолженность маржинального клиента | C32: у.е. | D32: 8000 | E32: 150000 | F32: 5000000 | G32: 1 | H32: Частично | I32: Объёмный | J32: MPORT → R2, C5 | K32: Через портфель к активам (см. MRG_PEN).
A33: MRG_RATE | B33: Ставка для клиента по маржинальному кредиту (деньги и ценные бумаги) | C33: % | D33: 0.12 | E33: 0.1 | F33: 0.08 | G33: 1 | H33: Управляемый | I33: Ценовой | J33: R2 | K33: Freedom (РК): базовая ставка НБРК + 4 п.п., не ниже 15%; T-Investments Premium ≈14–26% годовых [расчёт]. | L33: Ценовой рычаг: учитывать эластичность спроса на плечо.
A34: FUND_RATE | B34: Стоимость фондирования маржинального портфеля | C34: % | D34: 0.07 | E34: 0.07 | F34: 0.065 | G34: -1 | H34: Внешний | I34: Внешний | J34: R2 | K34: Внешний фактор: текущая стоимость фондирования, к ней применяется сценарий RATE_SHIFT.
A35: CL | B35: Кредитные потери по маржинальному портфелю, % в год | C35: % | D35: 0.005 | E35: 0.002 | F35: 0.001 | G35: -1 | H35: Частично | I35: Затратный | J35: C5 | K35: Условно; ориентир — данные риск-менеджмента.
A36: Валютообменные операции
A37: FX_PEN | B37: Доля фондированных клиентов, совершающих конвертации | C37: % | D37: 0.3 | E37: 0.5 | F37: 0.4 | G37: 1 | H37: Управляемый | I37: Объёмный | J37: FXVOLUME → R4 | K37: Условно: доля конвертирующих клиентов в открытых источниках не найдена.
A38: FX_VOL | B38: Объём конвертаций на конвертирующего клиента в год | C38: у.е. | D38: 5000 | E38: 100000 | F38: 10000000 | G38: 1 | H38: Частично | I38: Объёмный | J38: FXVOLUME → R4 | K38: Условно.
A39: FX_SPREAD | B39: Комиссия и спред за конвертацию, % от объёма | C39: % | D39: 0.005 | E39: 0.003 | F39: 0.0005 | G39: 1 | H39: Управляемый | I39: Ценовой | J39: R4 | K39: Условно; у Swissquote валютные операции ≈13% выручки (2025).
A40: Размещения и продукты
A41: PRD_PEN | B41: Доля фондированных клиентов, купивших размещения или продукты за год (ИК — доля клиентов-эмитентов, проведших размещение) | C41: % | D41: 0.08 | E41: 0.35 | F41: 0.05 | G41: 1 | H41: Управляемый | I41: Объёмный | J41: PRDVOLUME → R5 | K41: Условно; российские брокеры: комиссии за размещения выросли в 1,5 раза в 1П 2026.
A42: PRD_VOL | B42: Средний объём покупок продуктов на клиента в год (ИК — средний объём размещения) | C42: у.е. | D42: 3000 | E42: 80000 | F42: 50000000 | G42: 1 | H42: Частично | I42: Объёмный | J42: PRDVOLUME → R5 | K42: Условно.
...

Sheet Чувствительность
A1: Чувствительность маржинального дохода к драйверам
A2: Сколько у.е. МД в год даёт улучшение драйвера на 1% (относительно текущего значения) или на практический шаг, при прочих равных — в двух горизонтах: «год 1» (P&L плана) и «долгосрочно» (база сходится к NEW ÷ CHURN). Чувствительность — не приоритет: приоритет = ценность × достижимый сдвиг × вероятность ÷ трудозатраты.
J3: Базовый МД, год 1: | M3: =INDEX(Модель!$J$91:$JA$91,MATCH("MR|"&"BASE"&"|1",Модель!$J$6:$JA$6,0))+INDEX(Модель!$J$91:$JA$91,MATCH("AF|"&"BASE"&"|1",Модель!$J$6:$JA$6,0))+INDEX(Модель!$J$91:$JA$91,MATCH("IC|"&"BASE"&"|1",Модель!$J$6:$JA$6,0)) -> 81553114 | N3: Базовый МД, долгосрочно: | Q3: =INDEX(Модель!$J$91:$JA$91,MATCH("MR|"&"BASE"&"|3",Модель!$J$6:$JA$6,0))+INDEX(Модель!$J$91:$JA$91,MATCH("AF|"&"BASE"&"|3",Модель!$J$6:$JA$6,0))+INDEX(Модель!$J$91:$JA$91,MATCH("IC|"&"BASE"&"|3",Модель!$J$6:$JA$6,0)) -> 99380525
A4: Код | B4: Драйвер | C4: Ед. | D4: Направление | E4: Управляемость | F4: Тип рычага | G4: Значение: МР | H4: Значение: СК | I4: Значение: ИК | J4: ΔМД +1%, год 1: МР | K4: ΔМД +1%, год 1: СК | L4: ΔМД +1%, год 1: ИК | M4: ΔМД +1%, год 1: итого | N4: ΔМД +1%, долгосрочно: МР | O4: ΔМД +1%, долгосрочно: СК | P4: ΔМД +1%, долгосрочно: ИК | Q4: ΔМД +1%, долгосрочно: итого | R4: Доля от МД (долгосрочно) | S4: Ранг в группе (долгосрочно) | T4: Практический шаг | U4: ΔМД за шаг, год 1: итого | V4: ΔМД за шаг, долгосрочно: итого | W4: Комментарий | X4: ключ: объёмные и затратные | Y4: ключ: ценовые
A5: LEADS | B5: Заявки на открытие счёта за период (ИК — потенциальные клиенты в воронке продаж) | C5: шт. | D5: 1 | E5: Управляемый | F5: Объёмный | G5: =INDEX(Вводные!$D$13:$D$64,MATCH($A5,Вводные!$A$13:$A$64,0)) -> 300000 | H5: =INDEX(Вводные!$E$13:$E$64,MATCH($A5,Вводные!$A$13:$A$64,0)) -> 2000 | I5: =INDEX(Вводные!$F$13:$F$64,MATCH($A5,Вводные!$A$13:$A$64,0)) -> 120 | J5: =INDEX(Модель!$J$91:$JA$91,MATCH("MR|"&$A5&"|1",Модель!$J$6:$JA$6,0))-INDEX(Модель!$J$91:$JA$91,MATCH("MR|"&"BASE"&"|1",Модель!$J$6:$JA$6,0)) -> -42405.345 | K5: =INDEX(Модель!$J$91:$JA$91,MATCH("AF|"&$A5&"|1",Модель!$J$6:$JA$6,0))-INDEX(Модель!$J$91:$JA$91,MATCH("AF|"&"BASE"&"|1",Модель!$J$6:$JA$6,0)) -> -7984.08 | L5: =INDEX(Модель!$J$91:$JA$91,MATCH("IC|"&$A5&"|1",Модель!$J$6:$JA$6,0))-INDEX(Модель!$J$91:$JA$91,MATCH("IC|"&"BASE"&"|1",Модель!$J$6:$JA$6,0)) -> 4955.88 | M5: =SUM(J5:L5) -> -45433.545 | N5: =INDEX(Модель!$J$91:$JA$91,MATCH("MR|"&$A5&"|3",Модель!$J$6:$JA$6,0))-INDEX(Модель!$J$91:$JA$91,MATCH("MR|"&"BASE"&"|3",Модель!$J$6:$JA$6,0)) -> 407144.25 | O5: =INDEX(Модель!$J$91:$JA$91,MATCH("AF|"&$A5&"|3",Модель!$J$6:$JA$6,0))-INDEX(Модель!$J$91:$JA$91,MATCH("AF|"&"BASE"&"|3",Модель!$J$6:$JA$6,0)) -> 294524 | P5: =INDEX(Модель!$J$91:$JA$91,MATCH("IC|"&$A5&"|3",Модель!$J$6:$JA$6,0))-INDEX(Модель!$J$91:$JA$91,MATCH("IC|"&"BASE"&"|3",Модель!$J$6:$JA$6,0)) -> 298137 | Q5: =SUM(N5:P5) -> 999805.25 | R5: =IF($Q$3<>0,Q5/$Q$3,0) -> 0.010060374 | S5: =IF($E5="Внешний","",IF($F5="Ценовой",RANK(Y5,$Y$5:$Y$45),RANK(X5,$X$5:$X$45))) -> 4 | W5: В горизонте «год 1» рост привлечения снижает МД: CAC платится сразу, доход приходит позже. | X5: =IF(OR($E5="Внешний",$F5="Ценовой"),-1000000000000000,Q5)+ROW()/1000000000 -> 999805.25 | Y5: =IF($F5<>"Ценовой",-1000000000000000,Q5)+ROW()/1000000000 -> -1e+15
A6: CR_OPEN | B6: Конверсия: заявка → открытый счёт (KYC пройден; ИК — договор подписан) | C6: % | D6: 1 | E6: Управляемый | F6: Объёмный | G6: =INDEX(Вводные!$D$13:$D$64,MATCH($A6,Вводные!$A$13:$A$64,0)) -> 0.45 | H6: =INDEX(Вводные!$E$13:$E$64,MATCH($A6,Вводные!$A$13:$A$64,0)) -> 0.7 | I6: =INDEX(Вводные!$F$13:$F$64,MATCH($A6,Вводные!$A$13:$A$64,0)) -> 0.4 | J6: =INDEX(Модель!$J$91:$JA$91,MATCH("MR|"&$A6&"|1",Модель!$J$6:$JA$6,0))-INDEX(Модель!$J$91:$JA$91,MATCH("MR|"&"BASE"&"|1",Модель!$J$6:$JA$6,0)) -> -30705.345 | K6: =INDEX(Модель!$J$91:$JA$91,MATCH("AF|"&$A6&"|1",Модель!$J$6:$JA$6,0))-INDEX(Модель!$J$91:$JA$91,MATCH("AF|"&"BASE"&"|1",Модель!$J$6:$JA$6,0)) -> -7444.08 | L6: =INDEX(Модель!$J$91:$JA$91,MATCH("IC|"&$A6&"|1",Модель!$J$6:$JA$6,0))-INDEX(Модель!$J$91:$JA$91,MATCH("IC|"&"BASE"&"|1",Модель!$J$6:$JA$6,0)) -> 6815.88 | M6: =SUM(J6:L6) -> -31333.545 | N6: =INDEX(Модель!$J$91:$JA$91,MATCH("MR|"&$A6&"|3",Модель!$J$6:$JA$6,0))-INDEX(Модель!$J$91:$JA$91,MATCH("MR|"&"BASE"&"|3",Модель!$J$6:$JA$6,0)) -> 418844.25 | O6: =INDEX(Модель!$J$91:$JA$91,MATCH("AF|"&$A6&"|3",Модель!$J$6:$JA$6,0))-INDEX(Модель!$J$91:$JA$91,MATCH("AF|"&"BASE"&"|3",Модель!$J$6:$JA$6,0)) -> 295064 | P6: =INDEX(Модель!$J$91:$JA$91,MATCH("IC|"&$A6&"|3",Модель!$J$6:$JA$6,0))-INDEX(Модель!$J$91:$JA$91,MATCH("IC|"&"BASE"&"|3",Модель!$J$6:$JA$6,0)) -> 299997 | Q6: =SUM(N6:P6) -> 1013905.3 | R6: =IF($Q$3<>0,Q6/$Q$3,0) -> 0.010202253 | S6: =IF($E6="Внешний","",IF($F6="Ценовой",RANK(Y6,$Y$5:$Y$45),RANK(X6,$X$5:$X$45))) -> 3 | T6: 1 п.п. | U6: =IF(G6<>0,J6*0.01/(G6*Вводные!$D$5),0)+IF(H6<>0,K6*0.01/(H6*Вводные!$D$5),0)+IF(I6<>0,L6*0.01/(I6*Вводные!$D$5),0) -> -61828.8 | V6: =IF(G6<>0,N6*0.01/(G6*Вводные!$D$5),0)+IF(H6<>0,O6*0.01/(H6*Вводные!$D$5),0)+IF(I6<>0,P6*0.01/(I6*Вводные!$D$5),0) -> 2102277.5 | W6: В горизонте «год 1» рост привлечения снижает МД: CAC платится сразу, доход приходит позже. | X6: =IF(OR($E6="Внешний",$F6="Ценовой"),-1000000000000000,Q6)+ROW()/1000000000 -> 1013905.3 | Y6: =IF($F6<>"Ценовой",-1000000000000000,Q6)+ROW()/1000000000 -> -1e+15
A7: CR_FUND | B7: Конверсия: открытый счёт → фондированный (первое пополнение) | C7: % | D7: 1 | E7: Управляемый | F7: Объёмный | G7: =INDEX(Вводные!$D$13:$D$64,MATCH($A7,Вводные!$A$13:$A$64,0)) -> 0.55 | H7: =INDEX(Вводные!$E$13:$E$64,MATCH($A7,Вводные!$A$13:$A$64,0)) -> 0.8 | I7: =INDEX(Вводные!$F$13:$F$64,MATCH($A7,Вводные!$A$13:$A$64,0)) -> 0.75 | J7: =INDEX(Модель!$J$91:$JA$91,MATCH("MR|"&$A7&"|1",Модель!$J$6:$JA$6,0))-INDEX(Модель!$J$91:$JA$91,MATCH("MR|"&"BASE"&"|1",Модель!$J$6:$JA$6,0)) -> -30705.345 | K7: =INDEX(Модель!$J$91:$JA$91,MATCH("AF|"&$A7&"|1",Модель!$J$6:$JA$6,0))-INDEX(Модель!$J$91:$JA$91,MATCH("AF|"&"BASE"&"|1",Модель!$J$6:$JA$6,0)) -> -7444.08 | L7: =INDEX(Модель!$J$91:$JA$91,MATCH("IC|"&$A7&"|1",Модель!$J$6:$JA$6,0))-INDEX(Модель!$J$91:$JA$91,MATCH("IC|"&"BASE"&"|1",Модель!$J$6:$JA$6,0)) -> 6815.88 | M7: =SUM(J7:L7) -> -31333.545 | N7: =INDEX(Модель!$J$91:$JA$91,MATCH("MR|"&$A7&"|3",Модель!$J$6:$JA$6,0))-INDEX(Модель!$J$91:$JA$91,MATCH("MR|"&"BASE"&"|3",Модель!$J$6:$JA$6,0)) -> 418844.25 | O7: =INDEX(Модель!$J$91:$JA$91,MATCH("AF|"&$A7&"|3",Модель!$J$6:$JA$6,0))-INDEX(Модель!$J$91:$JA$91,MATCH("AF|"&"BASE"&"|3",Модель!$J$6:$JA$6,0)) -> 295064 | P7: =INDEX(Модель!$J$91:$JA$91,MATCH("IC|"&$A7&"|3",Модель!$J$6:$JA$6,0))-INDEX(Модель!$J$91:$JA$91,MATCH("IC|"&"BASE"&"|3",Модель!$J$6:$JA$6,0)) -> 299997 | Q7: =SUM(N7:P7) -> 1013905.3 | R7: =IF($Q$3<>0,Q7/$Q$3,0) -> 0.010202253 | S7: =IF($E7="Внешний","",IF($F7="Ценовой",RANK(Y7,$Y$5:$Y$45),RANK(X7,$X$5:$X$45))) -> 2 | T7: 1 п.п. | U7: =IF(G7<>0,J7*0.01/(G7*Вводные!$D$5),0)+IF(H7<>0,K7*0.01/(H7*Вводные!$D$5),0)+IF(I7<>0,L7*0.01/(I7*Вводные!$D$5),0) -> -56045.16 | V7: =IF(G7<>0,N7*0.01/(G7*Вводные!$D$5),0)+IF(H7<>0,O7*0.01/(H7*Вводные!$D$5),0)+IF(I7<>0,P7*0.01/(I7*Вводные!$D$5),0) -> 1530361 | W7: В горизонте «год 1» рост привлечения снижает МД: CAC платится сразу, доход приходит позже. | X7: =IF(OR($E7="Внешний",$F7="Ценовой"),-1000000000000000,Q7)+ROW()/1000000000 -> 1013905.3 | Y7: =IF($F7<>"Ценовой",-1000000000000000,Q7)+ROW()/1000000000 -> -1e+15
A8: CHURN | B8: Годовой отток фондированных клиентов (вывели активы ниже порога или закрыли счёт) | C8: % | D8: -1 | E8: Управляемый | F8: Объёмный | G8: =INDEX(Вводные!$D$13:$D$64,MATCH($A8,Вводные!$A$13:$A$64,0)) -> 0.12 | H8: =INDEX(Вводные!$E$13:$E$64,MATCH($A8,Вводные!$A$13:$A$64,0)) -> 0.06 | I8: =INDEX(Вводные!$F$13:$F$64,MATCH($A8,Вводные!$A$13:$A$64,0)) -> 0.08 | J8: =INDEX(Модель!$J$91:$JA$91,MATCH("MR|"&$A8&"|1",Модель!$J$6:$JA$6,0))-INDEX(Модель!$J$91:$JA$91,MATCH("MR|"&"BASE"&"|1",Модель!$J$6:$JA$6,0)) -> 23187.6 | K8: =INDEX(Модель!$J$91:$JA$91,MATCH("AF|"&$A8&"|1",Модель!$J$6:$JA$6,0))-INDEX(Модель!$J$91:$JA$91,MATCH("AF|"&"BASE"&"|1",Модель!$J$6:$JA$6,0)) -> 7518.15 | L8: =INDEX(Модель!$J$91:$JA$91,MATCH("IC|"&$A8&"|1",Модель!$J$6:$JA$6,0))-INDEX(Модель!$J$91:$JA$91,MATCH("IC|"&"BASE"&"|1",Модель!$J$6:$JA$6,0)) -> 10858.56 | M8: =SUM(J8:L8) -> 41564.31 | N8: =INDEX(Модель!$J$91:$JA$91,MATCH("MR|"&$A8&"|3",Модель!$J$6:$JA$6,0))-INDEX(Модель!$J$91:$JA$91,MATCH("MR|"&"BASE"&"|3",Модель!$J$6:$JA$6,0)) -> 483075 | O8: =INDEX(Модель!$J$91:$JA$91,MATCH("AF|"&$A8&"|3",Модель!$J$6:$JA$6,0))-INDEX(Модель!$J$91:$JA$91,MATCH("AF|"&"BASE"&"|3",Модель!$J$6:$JA$6,0)) -> 315014.14 | P8: =INDEX(Модель!$J$91:$JA$91,MATCH("IC|"&$A8&"|3",Модель!$J$6:$JA$6,0))-INDEX(Модель!$J$91:$JA$91,MATCH("IC|"&"BASE"&"|3",Модель!$J$6:$JA$6,0)) -> 308481.82 | Q8: =SUM(N8:P8) -> 1106571 | R8: =IF($Q$3<>0,Q8/$Q$3,0) -> 0.011134686 | S8: =IF($E8="Внешний","",IF($F8="Ценовой",RANK(Y8,$Y$5:$Y$45),RANK(X8,$X$5:$X$45))) -> 1 | T8: 1 п.п. | U8: =IF(G8<>0,J8*0.01/(G8*Вводные!$D$5),0)+IF(H8<>0,K8*0.01/(H8*Вводные!$D$5),0)+IF(I8<>0,L8*0.01/(I8*Вводные!$D$5),0) -> 454264.5 | V8: =IF(G8<>0,N8*0.01/(G8*Вводные!$D$5),0)+IF(H8<>0,O8*0.01/(H8*Вводные!$D$5),0)+IF(I8<>0,P8*0.01/(I8*Вводные!$D$5),0) -> 13131883 | W8: Долгосрочный эффект нелинеен (база = NEW ÷ CHURN): шаг в 1 п.п. оценён приблизительно. | X8: =IF(OR($E8="Внешний",$F8="Ценовой"),-1000000000000000,Q8)+ROW()/1000000000 -> 1106571 | Y8: =IF($F8<>"Ценовой",-1000000000000000,Q8)+ROW()/1000000000 -> -1e+15
A9: ACT | B9: Доля активных: среднемесячная доля фондированных клиентов с ≥1 операцией (сделка, пополнение, покупка продукта или подписки) | C9: % | D9: 1 | E9: Управляемый | F9: Объёмный | G9: =INDEX(Вводные!$D$13:$D$64,MATCH($A9,Вводные!$A$13:$A$64,0)) -> 0.35 | H9: =INDEX(Вводные!$E$13:$E$64,MATCH($A9,Вводные!$A$13:$A$64,0)) -> 0.55 | I9: =INDEX(Вводные!$F$13:$F$64,MATCH($A9,Вводные!$A$13:$A$64,0)) -> 0.8 | J9: =INDEX(Модель!$J$91:$JA$91,MATCH("MR|"&$A9&"|1",Модель!$J$6:$JA$6,0))-INDEX(Модель!$J$91:$JA$91,MATCH("MR|"&"BASE"&"|1",Модель!$J$6:$JA$6,0)) -> 122683.68 | K9: =INDEX(Модель!$J$91:$JA$91,MATCH("AF|"&$A9&"|1",Модель!$J$6:$JA$6,0))-INDEX(Модель!$J$91:$JA$91,MATCH("AF|"&"BASE"&"|1",Модель!$J$6:$JA$6,0)) -> 41884.92 | L9: =INDEX(Модель!$J$91:$JA$91,MATCH("IC|"&$A9&"|1",Модель!$J$6:$JA$6,0))-INDEX(Модель!$J$91:$JA$91,MATCH("IC|"&"BASE"&"|1",Модель!$J$6:$JA$6,0)) -> 60203.52 | M9: =SUM(J9:L9) -> 224772.12 | N9: =INDEX(Модель!$J$91:$JA$91,MATCH("MR|"&$A9&"|3",Модель!$J$6:$JA$6,0))-INDEX(Модель!$J$91:$JA$91,MATCH("MR|"&"BASE"&"|3",Модель!$J$6:$JA$6,0)) -> 149688 | O9: =INDEX(Модель!$J$91:$JA$91,MATCH("AF|"&$A9&"|3",Модель!$J$6:$JA$6,0))-INDEX(Модель!$J$91:$JA$91,MATCH("AF|"&"BASE"&"|3",Модель!$J$6:$JA$6,0)) -> 51744 | P9: =INDEX(Модель!$J$91:$JA$91,MATCH("IC|"&$A9&"|3",Модель!$J$6:$JA$6,0))-INDEX(Модель!$J$91:$JA$91,MATCH("IC|"&"BASE"&"|3",Модель!$J$6:$JA$6,0)) -> 67392 | Q9: =SUM(N9:P9) -> 268824 | R9: =IF($Q$3<>0,Q9/$Q$3,0) -> 0.0027049968 | S9: =IF($E9="Внешний","",IF($F9="Ценовой",RANK(Y9,$Y$5:$Y$45),RANK(X9,$X$5:$X$45))) -> 8 | T9: 1 п.п. | U9: =IF(G9<>0,J9*0.01/(G9*Вводные!$D$5),0)+IF(H9<>0,K9*0.01/(H9*Вводные!$D$5),0)+IF(I9<>0,L9*0.01/(I9*Вводные!$D$5),0) -> 501933.6 | V9: =IF(G9<>0,N9*0.01/(G9*Вводные!$D$5),0)+IF(H9<>0,O9*0.01/(H9*Вводные!$D$5),0)+IF(I9<>0,P9*0.01/(I9*Вводные!$D$5),0) -> 606000 | X9: =IF(OR($E9="Внешний",$F9="Ценовой"),-1000000000000000,Q9)+ROW()/1000000000 -> 268824 | Y9: =IF($F9<>"Ценовой",-1000000000000000,Q9)+ROW()/1000000000 -> -1e+15
A10: TPA | B10: Сделок в месяц на активного клиента | C10: шт./клиент | D10: 1 | E10: Частично | F10: Объёмный | G10: =INDEX(Вводные!$D$13:$D$64,MATCH($A10,Вводные!$A$13:$A$64,0)) -> 6 | H10: =INDEX(Вводные!$E$13:$E$64,MATCH($A10,Вводные!$A$13:$A$64,0)) -> 3.5 | I10: =INDEX(Вводные!$F$13:$F$64,MATCH($A10,Вводные!$A$13:$A$64,0)) -> 130 | J10: =INDEX(Модель!$J$91:$JA$91,MATCH("MR|"&$A10&"|1",Модель!$J$6:$JA$6,0))-INDEX(Модель!$J$91:$JA$91,MATCH("MR|"&"BASE"&"|1",Модель!$J$6:$JA$6,0)) -> 122683.68 | K10: =INDEX(Модель!$J$91:$JA$91,MATCH("AF|"&$A10&"|1",Модель!$J$6:$JA$6,0))-INDEX(Модель!$J$91:$JA$91,MATCH("AF|"&"BASE"&"|1",Модель!$J$6:$JA$6,0)) -> 41884.92 | L10: =INDEX(Модель!$J$91:$JA$91,MATCH("IC|"&$A10&"|1",Модель!$J$6:$JA$6,0))-INDEX(Модель!$J$91:$JA$91,MATCH("IC|"&"BASE"&"|1",Модель!$J$6:$JA$6,0)) -> 60203.52 | M10: =SUM(J10:L10) -> 224772.12 | N10: =INDEX(Модель!$J$91:$JA$91,MATCH("MR|"&$A10&"|3",Модель!$J$6:$JA$6,0))-INDEX(Модель!$J$91:$JA$91,MATCH("MR|"&"BASE"&"|3",Модель!$J$6:$JA$6,0)) -> 149688 | O10: =INDEX(Модель!$J$91:$JA$91,MATCH("AF|"&$A10&"|3",Модель!$J$6:$JA$6,0))-INDEX(Модель!$J$91:$JA$91,MATCH("AF|"&"BASE"&"|3",Модель!$J$6:$JA$6,0)) -> 51744 | P10: =INDEX(Модель!$J$91:$JA$91,MATCH("IC|"&$A10&"|3",Модель!$J$6:$JA$6,0))-INDEX(Модель!$J$91:$JA$91,MATCH("IC|"&"BASE"&"|3",Модель!$J$6:$JA$6,0)) -> 67392 | Q10: =SUM(N10:P10) -> 268824 | R10: =IF($Q$3<>0,Q10/$Q$3,0) -> 0.0027049968 | S10: =IF($E10="Внешний","",IF($F10="Ценовой",RANK(Y10,$Y$5:$Y$45),RANK(X10,$X$5:$X$45))) -> 7 | X10: =IF(OR($E10="Внешний",$F10="Ценовой"),-1000000000000000,Q10)+ROW()/1000000000 -> 268824 | Y10: =IF($F10<>"Ценовой",-1000000000000000,Q10)+ROW()/1000000000 -> -1e+15
A11: TICKET | B11: Средний объём сделки | C11: у.е. | D11: 1 | E11: Частично | F11: Объёмный | G11: =INDEX(Вводные!$D$13:$D$64,MATCH($A11,Вводные!$A$13:$A$64,0)) -> 800 | H11: =INDEX(Вводные!$E$13:$E$64,MATCH($A11,Вводные!$A$13:$A$64,0)) -> 15000 | I11: =INDEX(Вводные!$F$13:$F$64,MATCH($A11,Вводные!$A$13:$A$64,0)) -> 100000 | J11: =INDEX(Модель!$J$91:$JA$91,MATCH("MR|"&$A11&"|1",Модель!$J$6:$JA$6,0))-INDEX(Модель!$J$91:$JA$91,MATCH("MR|"&"BASE"&"|1",Модель!$J$6:$JA$6,0)) -> 122683.68 | K11: =INDEX(Модель!$J$91:$JA$91,MATCH("AF|"&$A11&"|1",Модель!$J$6:$JA$6,0))-INDEX(Модель!$J$91:$JA$91,MATCH("AF|"&"BASE"&"|1",Модель!$J$6:$JA$6,0)) -> 41884.92 | L11: =INDEX(Модель!$J$91:$JA$91,MATCH("IC|"&$A11&"|1",Модель!$J$6:$JA$6,0))-INDEX(Модель!$J$91:$JA$91,MATCH("IC|"&"BASE"&"|1",Модель!$J$6:$JA$6,0)) -> 60203.52 | M11: =SUM(J11:L11) -> 224772.12 | N11: =INDEX(Модель!$J$91:$JA$91,MATCH("MR|"&$A11&"|3",Модель!$J$6:$JA$6,0))-INDEX(Модель!$J$91:$JA$91,MATCH("MR|"&"BASE"&"|3",Модель!$J$6:$JA$6,0)) -> 149688 | O11: =INDEX(Модель!$J$91:$JA$91,MATCH("AF|"&$A11&"|3",Модель!$J$6:$JA$6,0))-INDEX(Модель!$J$91:$JA$91,MATCH("AF|"&"BASE"&"|3",Модель!$J$6:$JA$6,0)) -> 51744 | P11: =INDEX(Модель!$J$91:$JA$91,MATCH("IC|"&$A11&"|3",Модель!$J$6:$JA$6,0))-INDEX(Модель!$J$91:$JA$91,MATCH("IC|"&"BASE"&"|3",Модель!$J$6:$JA$6,0)) -> 67392 | Q11: =SUM(N11:P11) -> 268824 | R11: =IF($Q$3<>0,Q11/$Q$3,0) -> 0.0027049968 | S11: =IF($E11="Внешний","",IF($F11="Ценовой",RANK(Y11,$Y$5:$Y$45),RANK(X11,$X$5:$X$45))) -> 6 | X11: =IF(OR($E11="Внешний",$F11="Ценовой"),-1000000000000000,Q11)+ROW()/1000000000 -> 268824 | Y11: =IF($F11<>"Ценовой",-1000000000000000,Q11)+ROW()/1000000000 -> -1e+15
A12: TAKE | B12: Комиссия брокера, % от оборота (эффективная, с учётом тарифов и скидок) | C12: % | D12: 1 | E12: Управляемый | F12: Ценовой | G12: =INDEX(Вводные!$D$13:$D$64,MATCH($A12,Вводные!$A$13:$A$64,0)) -> 0.0015 | H12: =INDEX(Вводные!$E$13:$E$64,MATCH($A12,Вводные!$A$13:$A$64,0)) -> 0.001 | I12: =INDEX(Вводные!$F$13:$F$64,MATCH($A12,Вводные!$A$13:$A$64,0)) -> 0.0002 | J12: =INDEX(Модель!$J$91:$JA$91,MATCH("MR|"&$A12&"|1",Модель!$J$6:$JA$6,0))-INDEX(Модель!$J$91:$JA$91,MATCH("MR|"&"BASE"&"|1",Модель!$J$6:$JA$6,0)) -> 153354.6 | K12: =INDEX(Модель!$J$91:$JA$91,MATCH("AF|"&$A12&"|1",Модель!$J$6:$JA$6,0))-INDEX(Модель!$J$91:$JA$91,MATCH("AF|"&"BASE"&"|1",Модель!$J$6:$JA$6,0)) -> 52356.15 | L12: =INDEX(Модель!$J$91:$JA$91,MATCH("IC|"&$A12&"|1",Модель!$J$6:$JA$6,0))-INDEX(Модель!$J$91:$JA$91,MATCH("IC|"&"BASE"&"|1",Модель!$J$6:$JA$6,0)) -> 100339.2 | M12: =SUM(J12:L12) -> 306049.95 | N12: =INDEX(Модель!$J$91:$JA$91,MATCH("MR|"&$A12&"|3",Модель!$J$6:$JA$6,0))-INDEX(Модель!$J$91:$JA$91,MATCH("MR|"&"BASE"&"|3",Модель!$J$6:$JA$6,0)) -> 187110 | O12: =INDEX(Модель!$J$91:$JA$91,MATCH("AF|"&$A12&"|3",Модель!$J$6:$JA$6,0))-INDEX(Модель!$J$91:$JA$91,MATCH("AF|"&"BASE"&"|3",Модель!$J$6:$JA$6,0)) -> 64680 | P12: =INDEX(Модель!$J$91:$JA$91,MATCH("IC|"&$A12&"|3",Модель!$J$6:$JA$6,0))-INDEX(Модель!$J$91:$JA$91,MATCH("IC|"&"BASE"&"|3",Модель!$J$6:$JA$6,0)) -> 112320 | Q12: =SUM(N12:P12) -> 364110 | R12: =IF($Q$3<>0,Q12/$Q$3,0) -> 0.0036637963 | S12: =IF($E12="Внешний","",IF($F12="Ценовой",RANK(Y12,$Y$5:$Y$45),RANK(X12,$X$5:$X$45))) -> 3 | T12: 1 б.п. | U12: =IF(G12<>0,J12*0.0001/(G12*Вводные!$D$5),0)+IF(H12<>0,K12*0.0001/(H12*Вводные!$D$5),0)+IF(I12<>0,L12*0.0001/(I12*Вводные!$D$5),0) -> 6562885.5 | V12: =IF(G12<>0,N12*0.0001/(G12*Вводные!$D$5),0)+IF(H12<>0,O12*0.0001/(H12*Вводные!$D$5),0)+IF(I12<>0,P12*0.0001/(I12*Вводные!$D$5),0) -> 7510200 | W12: Ценовой рычаг: эффект при неизменных объёмах — учитывать эластичность. | X12: =IF(OR($E12="Внешний",$F12="Ценовой"),-1000000000000000,Q12)+ROW()/1000000000 -> -1e+15 | Y12: =IF($F12<>"Ценовой",-1000000000000000,Q12)+ROW()/1000000000 -> 364110
